Workbook

Sheet Parametros_PNAE
A1: Parâmetros do PNAE — 2026
A2: Fonte: Resolução CD/FNDE nº 1, de 18 de fevereiro de 2026 (altera a Resolução CD/FNDE nº 6/2020). Reajuste médio de 14,35% em relação a 2025. Valores em vigor desde a primeira parcela de 2026.
A4: Modalidade | B4: Valor per capita (R$/dia)
A5: Creche | B5: 1.57
A6: Pré-escola | B6: 0.82
A7: Fundamental | B7: 0.57
A8: Médio | B8: 0.57
A9: EJA | B9: 0.57
A10: Indígena/Quilombola | B10: 0.98
A11: AEE (contraturno) | B11: 0.78
A13: Dias letivos (ano) | B13: 200
A15: Faixas de Porte da Escola (classificação didática)
A16: Matrículas (mínimo) | B16: Porte
A17: 0 | B17: Pequena
A18: 201 | B18: Média
A19: 401 | B19: Grande
A20: Faixas criadas para fins didáticos deste curso

Sheet Simulador_Escola
A1: Projeto 1 — Simulador de Repasse do PNAE
A2: Escola e matrículas fictícias, criadas para fins didáticos. Valores per capita, dias letivos e a regra de cálculo do repasse são reais (Resolução CD/FNDE nº 1/2026). O bairro é real, no município de Osasco/SP.
A4: Nome da Escola (fictício) | B4: EMEB Vila Quitaúna
A5: Bairro | B5: Quitaúna
A6: Município | B6: Osasco/SP
A8: Matrículas por modalidade (ano letivo projetado)
A9: Modalidade | B9: Matrículas | C9: Valor per capita (R$/dia)
A10: Creche | B10: 60 | C10: =VLOOKUP(A10,Parametros_PNAE!A5:B11,2,FALSE) -> 1.57
A11: Pré-escola | B11: 80 | C11: =VLOOKUP(A11,Parametros_PNAE!A6:B12,2,FALSE) -> 0.82
A12: Fundamental | B12: 50 | C12: =VLOOKUP(A12,Parametros_PNAE!A7:B13,2,FALSE) -> 0.57
A13: Médio | B13: 0 | C13: =VLOOKUP(A13,Parametros_PNAE!A8:B14,2,FALSE) -> 0.57
A14: EJA | B14: 0 | C14: =VLOOKUP(A14,Parametros_PNAE!A9:B15,2,FALSE) -> 0.57
A15: Indígena/Quilombola | B15: 0 | C15: =VLOOKUP(A15,Parametros_PNAE!A10:B16,2,FALSE) -> 0.98
A16: AEE (contraturno) | B16: 0 | C16: =VLOOKUP(A16,Parametros_PNAE!A11:B17,2,FALSE) -> 0.78
A17: Total de Matrículas | B17: =SUM(B10:B16) -> 190
A19: Porte da Escola | B19: =VLOOKUP(B17,Parametros_PNAE!$A$17:$B$19,2,TRUE()) -> Pequena
A20: Dias letivos | B20: =Parametros_PNAE!B13 -> 200
A21: Repasse Anual Estimado (R$) | B21: =SUMPRODUCT(B10:B16,C10:C16)*200 -> 37660
A23: Elegibilidade para complementação municipal (regra de exercício) | C23: =IF(OR(Simulador_Escola!B19="Pequena",Simulador_Escola!B10>0,Simulador_Escola!B11>0),"Elegível","Não Elegível") -> Elegível
A24: Regra criada apenas para praticar SE aninhado e E/OU; não reproduz nenhum critério oficial de complementação.
A26: Modelo para Simulação | B26: Fator de Ajuste | C26: 0
A27: Modalidade | B27: Matrículas | C27: 0 | D27: Valor per capita (R$/dia)
A28: Creche | B28: 60 | C28: =B28*(1+$C$26) -> 60 | D28: =C10 -> 1.57
A29: Pré-escola | B29: 80 | C29: =B29*(1+$C$26) -> 80 | D29: =C11 -> 0.82
A30: Fundamental | B30: 50 | C30: =B30*(1+$C$26) -> 50 | D30: =C12 -> 0.57
A31: Médio | B31: 0 | C31: =B31*(1+$C$26) -> 0 | D31: =C13 -> 0.57
A32: EJA | B32: 0 | C32: =B32*(1+$C$26) -> 0 | D32: =C14 -> 0.57
A33: Indígena/Quilombola | B33: 0 | C33: =B33*(1+$C$26) -> 0 | D33: =C15 -> 0.98
A34: AEE (contraturno) | B34: 0 | C34: =B34*(1+$C$26) -> 0 | D34: =C16 -> 0.78
A35: Total de Matrículas e Repasse | C35: =SUM(C28:C34) -> 190 | D35: =SUMPRODUCT(C28:C34,D28:D34)*B20 -> 37660
A37: TABELA DE DADOS -> Selecionar de A39 até C48 -> Dados/Teste de Hipótese/Tabela de Dados -> Linha não preencher e Coluna informar C26
A39: Fator de Variação | B39: =C35 -> 190 | C39: =D35 -> 37660
A40: -0.2 | B40: 152 | C40: 30128
A41: -0.15 | B41: 161.5 | C41: 32011
A42: -0.1 | B42: 171 | C42: 33894
A43: -0.05 | B43: 180.5 | C43: 35777
A44: 0 | B44: 190 | C44: 37660
A45: 0.05 | B45: 199.5 | C45: 39543
A46: 0.1 | B46: 209 | C46: 41426
A47: 0.15 | B47: 218.5 | C47: 43309
...
